Workbook
Name ExternalData_1: marche!$A$1:$AA$367
Name ExternalData_1: dados!$A$1:$R$1048
Name ExternalData_2: mambo!$A$1:$AK$499

Sheet dados
A1: Código | B1: Descrição | C1: Departamento | D1: Categoria/Setor | E1: Marca | F1: Famlíia | G1: Código do Fabricante | H1: Código de Barras | I1: SKU Monitorado | J1: Website Monitorado | K1: URL Produto Monitorado | L1: Data | M1: Média Preço Normal | N1: Média Preço Oferta | O1: Leituras | P1: Leituras com disponibilidade | Q1: URL Monitor | R1: Desvio Média Preço % | S1: Marca Target
A2: 1038723 | B2: Café Torrado e Moído Extraforte Pilão Pacote 500g | C2: Alimentos | D2: Básico da despensa | E2: pa | H2: 7896089013399 | I2: 1038723 | J2: www.paodeacucar.com | K2: https://www.paodeacucar.com/produto/292186/cafe-torrado-e-moido-extraforte-pilao-pacote-500g | L2: 46089 | M2: 27.49 | N2: 27.49 | O2: 22 | P2: 22 | Q2: https://monitor.precifica.com.br/index.php/Produtos?act=edit&id=15847066 | R2: 28.4 | S2: =COUNTIF('Marcas Target'!A:A,dados!$E2)>0 -> FALSE
A3: 1038723 | B3: Café Torrado e Moído Extraforte Pilão Pacote 500g | C3: Alimentos | D3: Básico da despensa | E3: pa | H3: 7896089013399 | I3: 1038723 | J3: www.paodeacucar.com | K3: https://www.paodeacucar.com/produto/292186/cafe-torrado-e-moido-extraforte-pilao-pacote-500g | L3: 46088 | M3: 27.49 | N3: 27.49 | O3: 24 | P3: 24 | Q3: https://monitor.precifica.com.br/index.php/Produtos?act=edit&id=15847066 | R3: 28.4 | S3: =COUNTIF('Marcas Target'!A:A,dados!$E3)>0 -> FALSE
A4: 1038723 | B4: Café Torrado e Moído Extraforte Pilão Pacote 500g | C4: Alimentos | D4: Básico da despensa | E4: pa | H4: 7896089013399 | I4: 1038723 | J4: www.paodeacucar.com | K4: https://www.paodeacucar.com/produto/292186/cafe-torrado-e-moido-extraforte-pilao-pacote-500g | L4: 46087 | M4: 27.49 | N4: 27.49 | O4: 24 | P4: 17 | Q4: https://monitor.precifica.com.br/index.php/Produtos?act=edit&id=15847066 | R4: 28.4 | S4: =COUNTIF('Marcas Target'!A:A,dados!$E4)>0 -> FALSE
A5: 0183567 | B5: Café Torrado e Moído Extraforte 3 Corações Pacote 500g | C5: Alimentos | D5: Básico da despensa | E5: pa | H5: 7896005801529 | I5: 0183567 | J5: www.paodeacucar.com | K5: https://www.paodeacucar.com/produto/57156/cafe-torrado-e-moido-extraforte-3-coracoes-pacote-500g | L5: 46089 | M5: 27.99 | N5: 27.99 | O5: 22 | P5: 22 | Q5: https://monitor.precifica.com.br/index.php/Produtos?act=edit&id=15847427 | S5: =COUNTIF('Marcas Target'!A:A,dados!$E5)>0 -> FALSE
A6: 0183567 | B6: Café Torrado e Moído Extraforte 3 Corações Pacote 500g | C6: Alimentos | D6: Básico da despensa | E6: pa | H6: 7896005801529 | I6: 0183567 | J6: www.paodeacucar.com | K6: https://www.paodeacucar.com/produto/57156/cafe-torrado-e-moido-extraforte-3-coracoes-pacote-500g | L6: 46088 | M6: 27.99 | N6: 27.99 | O6: 24 | P6: 23 | Q6: https://monitor.precifica.com.br/index.php/Produtos?act=edit&id=15847427 | S6: =COUNTIF('Marcas Target'!A:A,dados!$E6)>0 -> FALSE
A7: 0183567 | B7: Café Torrado e Moído Extraforte 3 Corações Pacote 500g | C7: Alimentos | D7: Básico da despensa | E7: pa | H7: 7896005801529 | I7: 0183567 | J7: www.paodeacucar.com | K7: https://www.paodeacucar.com/produto/57156/cafe-torrado-e-moido-extraforte-3-coracoes-pacote-500g | L7: 46087 | M7: 27.99 | N7: 27.99 | O7: 24 | P7: 23 | Q7: https://monitor.precifica.com.br/index.php/Produtos?act=edit&id=15847427 | S7: =COUNTIF('Marcas Target'!A:A,dados!$E7)>0 -> FALSE
A8: 0590655 | B8: Café Torrado e Moído Tradicional 3 Corações Pacote 500g | C8: Alimentos | D8: Básico da despensa | E8: pa | H8: 7896005800010 | I8: 0590655 | J8: www.paodeacucar.com | K8: https://www.paodeacucar.com/produto/82810/cafe-torrado-e-moido-tradicional-3-coracoes-pacote-500g | L8: 46089 | M8: 27.99 | N8: 27.99 | O8: 22 | P8: 22 | Q8: https://monitor.precifica.com.br/index.php/Produtos?act=edit&id=15847426 | S8: =COUNTIF('Marcas Target'!A:A,dados!$E8)>0 -> FALSE
A9: 0590655 | B9: Café Torrado e Moído Tradicional 3 Corações Pacote 500g | C9: Alimentos | D9: Básico da despensa | E9: pa | H9: 7896005800010 | I9: 0590655 | J9: www.paodeacucar.com | K9: https://www.paodeacucar.com/produto/82810/cafe-torrado-e-moido-tradicional-3-coracoes-pacote-500g | L9: 46088 | M9: 27.99 | N9: 27.99 | O9: 24 | P9: 24 | Q9: https://monitor.precifica.com.br/index.php/Produtos?act=edit&id=15847426 | S9: =COUNTIF('Marcas Target'!A:A,dados!$E9)>0 -> FALSE
A10: 0590655 | B10: Café Torrado e Moído Tradicional 3 Corações Pacote 500g | C10: Alimentos | D10: Básico da despensa | E10: pa | H10: 7896005800010 | I10: 0590655 | J10: www.paodeacucar.com | K10: https://www.paodeacucar.com/produto/82810/cafe-torrado-e-moido-tradicional-3-coracoes-pacote-500g | L10: 46087 | M10: 29.9 | N10: 29.9 | O10: 24 | P10: 22 | Q10: https://monitor.precifica.com.br/index.php/Produtos?act=edit&id=15847426 | S10: =COUNTIF('Marcas Target'!A:A,dados!$E10)>0 -> FALSE
A11: 0463478 | B11: Café Torrado e Moído a Vácuo Tradicional 3 Corações Pacote 500g | C11: Alimentos | D11: Básico da despensa | E11: pa | H11: 7896005800188 | I11: 0463478 | J11: www.paodeacucar.com | K11: https://www.paodeacucar.com/produto/101961 | L11: 46089 | M11: 27.99 | N11: 27.99 | O11: 22 | P11: 12 | Q11: https://monitor.precifica.com.br/index.php/Produtos?act=edit&id=15847436 | S11: =COUNTIF('Marcas Target'!A:A,dados!$E11)>0 -> FALSE
A12: 0463478 | B12: Café Torrado e Moído a Vácuo Tradicional 3 Corações Pacote 500g | C12: Alimentos | D12: Básico da despensa | E12: pa | H12: 7896005800188 | I12: 0463478 | J12: www.paodeacucar.com | K12: https://www.paodeacucar.com/produto/101961 | L12: 46088 | M12: 27.99 | N12: 27.99 | O12: 24 | P12: 11 | Q12: https://monitor.precifica.com.br/index.php/Produtos?act=edit&id=15847436 | S12: =COUNTIF('Marcas Target'!A:A,dados!$E12)>0 -> FALSE
A13: 0463478 | B13: Café Torrado e Moído a Vácuo Tradicional 3 Corações Pacote 500g | C13: Alimentos | D13: Básico da despensa | E13: pa | H13: 7896005800188 | I13: 0463478 | J13: www.paodeacucar.com | K13: https://www.paodeacucar.com/produto/101961 | L13: 46087 | M13: 31.67 | N13: 31.67 | O13: 24 | P13: 19 | Q13: https://monitor.precifica.com.br/index.php/Produtos?act=edit&id=15847436 | S13: =COUNTIF('Marcas Target'!A:A,dados!$E13)>0 -> FALSE
A14: 1038722 | B14: Café Torrado e Moído a Vácuo Extraforte Pilão Pacote 500g | C14: Alimentos | D14: Básico da despensa | E14: pa | H14: 7896089013405 | I14: 1038722 | J14: www.paodeacucar.com | K14: https://www.paodeacucar.com/produto/292183/cafe-torrado-e-moido-a-vacuo-extraforte-pilao-pacote-500g | L14: 46089 | M14: 27.49 | N14: 27.49 | O14: 22 | P14: 22 | Q14: https://monitor.precifica.com.br/index.php/Produtos?act=edit&id=15969083 | R14: 28.4 | S14: =COUNTIF('Marcas Target'!A:A,dados!$E14)>0 -> FALSE
A15: 1038722 | B15: Café Torrado e Moído a Vácuo Extraforte Pilão Pacote 500g | C15: Alimentos | D15: Básico da despensa | E15: pa | H15: 7896089013405 | I15: 1038722 | J15: www.paodeacucar.com | K15: https://www.paodeacucar.com/produto/292183/cafe-torrado-e-moido-a-vacuo-extraforte-pilao-pacote-500g | L15: 46088 | M15: 27.49 | N15: 27.49 | O15: 24 | P15: 24 | Q15: https://monitor.precifica.com.br/index.php/Produtos?act=edit&id=15969083 | R15: 28.4 | S15: =COUNTIF('Marcas Target'!A:A,dados!$E15)>0 -> FALSE
A16: 1038722 | B16: Café Torrado e Moído a Vácuo Extraforte Pilão Pacote 500g | C16: Alimentos | D16: Básico da despensa | E16: pa | H16: 7896089013405 | I16: 1038722 | J16: www.paodeacucar.com | K16: https://www.paodeacucar.com/produto/292183/cafe-torrado-e-moido-a-vacuo-extraforte-pilao-pacote-500g | L16: 46087 | M16: 28.44 | N16: 28.44 | O16: 24 | P16: 20 | Q16: https://monitor.precifica.com.br/index.php/Produtos?act=edit&id=15969083 | R16: 32.84 | S16: =COUNTIF('Marcas Target'!A:A,dados!$E16)>0 -> FALSE
A17: 0798341 | B17: Café Solúvel NESCAFÉ Matinal 100g | C17: Alimentos | D17: Básico da despensa | E17: pa | H17: 7891000315507 | I17: 0798341 | J17: www.paodeacucar.com | K17: https://www.paodeacucar.com/produto/137096/cafe-soluvel-nescafe-matinal-100g | L17: 46089 | M17: 27.19 | N17: 27.19 | O17: 22 | P17: 22 | Q17: https://monitor.precifica.com.br/index.php/Produtos?act=edit&id=15969023 | S17: =COUNTIF('Marcas Target'!A:A,dados!$E17)>0 -> FALSE
A18: 0798341 | B18: Café Solúvel NESCAFÉ Matinal 100g | C18: Alimentos | D18: Básico da despensa | E18: pa | H18: 7891000315507 | I18: 0798341 | J18: www.paodeacucar.com | K18: https://www.paodeacucar.com/produto/137096/cafe-soluvel-nescafe-matinal-100g | L18: 46088 | M18: 31.62 | N18: 31.62 | O18: 24 | P18: 23 | Q18: https://monitor.precifica.com.br/index.php/Produtos?act=edit&id=15969023 | S18: =COUNTIF('Marcas Target'!A:A,dados!$E18)>0 -> FALSE
A19: 0798341 | B19: Café Solúvel NESCAFÉ Matinal 100g | C19: Alimentos | D19: Básico da despensa | E19: pa | H19: 7891000315507 | I19: 0798341 | J19: www.paodeacucar.com | K19: https://www.paodeacucar.com/produto/137096/cafe-soluvel-nescafe-matinal-100g | L19: 46087 | M19: 30.31 | N19: 30.31 | O19: 24 | P19: 24 | Q19: https://monitor.precifica.com.br/index.php/Produtos?act=edit&id=15969023 | S19: =COUNTIF('Marcas Target'!A:A,dados!$E19)>0 -> FALSE
A20: 0250672 | B20: Café Solúvel Granulado Extraforte Nescafé Original Vidro 100g | C20: Alimentos | D20: Básico da despensa | E20: pa | H20: 7891000300503 | I20: 0250672 | J20: www.paodeacucar.com | K20: https://www.paodeacucar.com/produto/152381/cafe-soluvel-granulado-extraforte-nescafe-original-vidro-100g | L20: 46089 | M20: 27.19 | N20: 27.19 | O20: 22 | P20: 22 | Q20: https://monitor.precifica.com.br/index.php/Produtos?act=edit&id=15968936 | S20: =COUNTIF('Marcas Target'!A:A,dados!$E20)>0 -> FALSE
A21: 0250672 | B21: Café Solúvel Granulado Extraforte Nescafé Original Vidro 100g | C21: Alimentos | D21: Básico da despensa | E21: pa | H21: 7891000300503 | I21: 0250672 | J21: www.paodeacucar.com | K21: https://www.paodeacucar.com/produto/152381/cafe-soluvel-granulado-extraforte-nescafe-original-vidro-100g | L21: 46088 | M21: 31.16 | N21: 31.16 | O21: 24 | P21: 24 | Q21: https://monitor.precifica.com.br/index.php/Produtos?act=edit&id=15968936 | S21: =COUNTIF('Marcas Target'!A:A,dados!$E21)>0 -> FALSE
A22: 0250672 | B22: Café Solúvel Granulado Extraforte Nescafé Original Vidro 100g | C22: Alimentos | D22: Básico da despensa | E22: pa | H22: 7891000300503 | I22: 0250672 | J22: www.paodeacucar.com | K22: https://www.paodeacucar.com/produto/152381/cafe-soluvel-granulado-extraforte-nescafe-original-vidro-100g | L22: 46087 | M22: 30.44 | N22: 30.44 | O22: 24 | P22: 23 | Q22: https://monitor.precifica.com.br/index.php/Produtos?act=edit&id=15968936 | S22: =COUNTIF('Marcas Target'!A:A,dados!$E22)>0 -> FALSE
A23: 0561495 | B23: Café Torrado e Moído Tradicional Melitta Caixa 500g | C23: Alimentos | D23: Básico da despensa | E23: pa | H23: 7891021006125 | I23: 0561495 | J23: www.paodeacucar.com | K23: https://www.paodeacucar.com/produto/37565/cafe-torrado-e-moido-tradicional-melitta-caixa-500g | L23: 46089 | M23: 38.99 | N23: 38.99 | O23: 22 | P23: 11 | Q23: https://monitor.precifica.com.br/index.php/Produtos?act=edit&id=15968989 | S23: =COUNTIF('Marcas Target'!A:A,dados!$E23)>0 -> FALSE
A24: 0561495 | B24: Café Torrado e Moído Tradicional Melitta Caixa 500g | C24: Alimentos | D24: Básico da despensa | E24: pa | H24: 7891021006125 | I24: 0561495 | J24: www.paodeacucar.com | K24: https://www.paodeacucar.com/produto/37565/cafe-torrado-e-moido-tradicional-melitta-caixa-500g | L24: 46088 | M24: 38.99 | N24: 38.99 | O24: 24 | P24: 15 | Q24: https://monitor.precifica.com.br/index.php/Produtos?act=edit&id=15968989 | S24: =COUNTIF('Marcas Target'!A:A,dados!$E24)>0 -> FALSE
A25: 0561495 | B25: Café Torrado e Moído Tradicional Melitta Caixa 500g | C25: Alimentos | D25: Básico da despensa | E25: pa | H25: 7891021006125 | I25: 0561495 | J25: www.paodeacucar.com | K25: https://www.paodeacucar.com/produto/37565/cafe-torrado-e-moido-tradicional-melitta-caixa-500g | L25: 46087 | M25: 38.99 | N25: 38.99 | O25: 24 | P25: 13 | Q25: https://monitor.precifica.com.br/index.php/Produtos?act=edit&id=15968989 | S25: =COUNTIF('Marcas Target'!A:A,dados!$E25)>0 -> FALSE
A26: 1042369 | B26: Café em Cápsula Torrado e Moído Espresso Vibrante Tres Caixa 80g 10 Unidades | C26: Alimentos | D26: Básico da despensa | E26: pa | H26: 7896005805015 | I26: 1042369 | J26: www.paodeacucar.com | K26: https://www.paodeacucar.com/produto/302325/cafe-em-capsula-torrado-e-moido-espresso-vibrante-tres-caixa-80g-10-unidades | L26: 46089 | M26: 26.99 | N26: 26.99 | O26: 22 | P26: 11 | Q26: https://monitor.precifica.com.br/index.php/Produtos?act=edit&id=15969093 | R26: 50.03 | S26: =COUNTIF('Marcas Target'!A:A,dados!$E26)>0 -> FALSE
A27: 1042369 | B27: Café em Cápsula Torrado e Moído Espresso Vibrante Tres Caixa 80g 10 Unidades | C27: Alimentos | D27: Básico da despensa | E27: pa | H27: 7896005805015 | I27: 1042369 | J27: www.paodeacucar.com | K27: https://www.paodeacucar.com/produto/302325/cafe-em-capsula-torrado-e-moido-espresso-vibrante-tres-caixa-80g-10-unidades | L27: 46088 | M27: 26.99 | N27: 26.99 | O27: 24 | P27: 19 | Q27: https://monitor.precifica.com.br/index.php/Produtos?act=edit&id=15969093 | R27: 50.03 | S27: =COUNTIF('Marcas Target'!A:A,dados!$E27)>0 -> FALSE
A28: 1042369 | B28: Café em Cápsula Torrado e Moído Espresso Vibrante Tres Caixa 80g 10 Unidades | C28: Alimentos | D28: Básico da despensa | E28: pa | H28: 7896005805015 | I28: 1042369 | J28: www.paodeacucar.com | K28: https://www.paodeacucar.com/produto/302325/cafe-em-capsula-torrado-e-moido-espresso-vibrante-tres-caixa-80g-10-unidades | L28: 46087 | M28: 26.99 | N28: 26.99 | O28: 24 | P28: 9 | Q28: https://monitor.precifica.com.br/index.php/Produtos?act=edit&id=15969093 | R28: 50.03 | S28: =COUNTIF('Marcas Target'!A:A,dados!$E28)>0 -> FALSE
A29: 1042366 | B29: Café em Cápsula Torrado e Moído Espresso Supremo 3 Corações Caixa 10 Unidades 8g Cada | C29: Alimentos | D29: Básico da despensa | E29: pa | H29: 7896005805008 | I29: 1042366 | J29: www.paodeacucar.com | K29: https://www.paodeacucar.com/produto/297372/cafe-em-capsula-torrado-e-moido-espresso-supremo-3-coracoes-caixa-10-unidades-8g-cada | L29: 46089 | M29: 26.99 | N29: 26.99 | O29: 22 | P29: 16 | Q29: https://monitor.precifica.com.br/index.php/Produtos?act=edit&id=15969091 | R29: 50.03 | S29: =COUNTIF('Marcas Target'!A:A,dados!$E29)>0 -> FALSE
A30: 1042366 | B30: Café em Cápsula Torrado e Moído Espresso Supremo 3 Corações Caixa 10 Unidades 8g Cada | C30: Alimentos | D30: Básico da despensa | E30: pa | H30: 7896005805008 | I30: 1042366 | J30: www.paodeacucar.com | K30: https://www.paodeacucar.com/produto/297372/cafe-em-capsula-torrado-e-moido-espresso-supremo-3-coracoes-caixa-10-unidades-8g-cada | L30: 46088 | M30: 26.99 | N30: 26.99 | O30: 24 | P30: 18 | Q30: https://monitor.precifica.com.br/index.php/Produtos?act=edit&id=15969091 | R30: 50.03 | S30: =COUNTIF('Marcas Target'!A:A,dados!$E30)>0 -> FALSE
A31: 1042366 | B31: Café em Cápsula Torrado e Moído Espresso Supremo 3 Corações Caixa 10 Unidades 8g Cada | C31: Alimentos | D31: Básico da despensa | E31: pa | H31: 7896005805008 | I31: 1042366 | J31: www.paodeacucar.com | K31: https://www.paodeacucar.com/produto/297372/cafe-em-capsula-torrado-e-moido-espresso-supremo-3-coracoes-caixa-10-unidades-8g-cada | L31: 46087 | M31: 23.96 | N31: 23.96 | O31: 24 | P31: 7 | Q31: https://monitor.precifica.com.br/index.php/Produtos?act=edit&id=15969091 | R31: 33.19 | S31: =COUNTIF('Marcas Target'!A:A,dados!$E31)>0 -> FALSE
A32: 1042611 | B32: Café em Cápsula Torrado e Moído Espresso Descafeinado Tres Caixa 80g 10 Unidades | C32: Alimentos | D32: Básico da despensa | E32: pa | H32: 7896005805022 | I32: 1042611 | J32: www.paodeacucar.com | K32: https://www.paodeacucar.com/produto/302305/cafe-em-capsula-torrado-e-moido-espresso-descafeinado-tres-caixa-80g-10-unidades | L32: 46089 | M32: 26.99 | N32: 26.99 | O32: 22 | P32: 22 | Q32: https://monitor.precifica.com.br/index.php/Produtos?act=edit&id=15969097 | R32: 50.03 | S32: =COUNTIF('Marcas Target'!A:A,dados!$E32)>0 -> FALSE
A33: 1042611 | B33: Café em Cápsula Torrado e Moído Espresso Descafeinado Tres Caixa 80g 10 Unidades | C33: Alimentos | D33: Básico da despensa | E33: pa | H33: 7896005805022 | I33: 1042611 | J33: www.paodeacucar.com | K33: https://www.paodeacucar.com/produto/302305/cafe-em-capsula-torrado-e-moido-espresso-descafeinado-tres-caixa-80g-10-unidades | L33: 46088 | M33: 26.99 | N33: 26.99 | O33: 24 | P33: 24 | Q33: https://monitor.precifica.com.br/index.php/Produtos?act=edit&id=15969097 | R33: 50.03 | S33: =COUNTIF('Marcas Target'!A:A,dados!$E33)>0 -> FALSE
A34: 1042611 | B34: Café em Cápsula Torrado e Moído Espresso Descafeinado Tres Caixa 80g 10 Unidades | C34: Alimentos | D34: Básico da despensa | E34: pa | H34: 7896005805022 | I34: 1042611 | J34: www.paodeacucar.com | K34: https://www.paodeacucar.com/produto/302305/cafe-em-capsula-torrado-e-moido-espresso-descafeinado-tres-caixa-80g-10-unidades | L34: 46087 | M34: 26.99 | N34: 26.99 | O34: 24 | P34: 24 | Q34: https://monitor.precifica.com.br/index.php/Produtos?act=edit&id=15969097 | R34: 50.03 | S34: =COUNTIF('Marcas Target'!A:A,dados!$E34)>0 -> FALSE
A35: 1042367 | B35: Café em Cápsula Torrado e Moído Espresso Pleno Tres Caixa 80g 10 Unidades | C35: Alimentos | D35: Básico da despensa | E35: pa | H35: 7896005804995 | I35: 1042367 | J35: www.paodeacucar.com | K35: https://www.paodeacucar.com/produto/302245/cafe-em-capsula-torrado-e-moido-espresso-pleno-tres-caixa-80g-10-unidades | L35: 46089 | M35: 26.99 | N35: 26.99 | O35: 22 | P35: 12 | Q35: https://monitor.precifica.com.br/index.php/Produtos?act=edit&id=15969092 | R35: 50.03 | S35: =COUNTIF('Marcas Target'!A:A,dados!$E35)>0 -> FALSE
A36: 1042367 | B36: Café em Cápsula Torrado e Moído Espresso Pleno Tres Caixa 80g 10 Unidades | C36: Alimentos | D36: Básico da despensa | E36: pa | H36: 7896005804995 | I36: 1042367 | J36: www.paodeacucar.com | K36: https://www.paodeacucar.com/produto/302245/cafe-em-capsula-torrado-e-moido-espresso-pleno-tres-caixa-80g-10-unidades | L36: 46088 | M36: 26.99 | N36: 26.99 | O36: 24 | P36: 19 | Q36: https://monitor.precifica.com.br/index.php/Produtos?act=edit&id=15969092 | R36: 50.03 | S36: =COUNTIF('Marcas Target'!A:A,dados!$E36)>0 -> FALSE
A37: 1042367 | B37: Café em Cápsula Torrado e Moído Espresso Pleno Tres Caixa 80g 10 Unidades | C37: Alimentos | D37: Básico da despensa | E37: pa | H37: 7896005804995 | I37: 1042367 | J37: www.paodeacucar.com | K37: https://www.paodeacucar.com/produto/302245/cafe-em-capsula-torrado-e-moido-espresso-pleno-tres-caixa-80g-10-unidades | L37: 46087 | M37: 24.31 | N37: 24.31 | O37: 24 | P37: 5 | Q37: https://monitor.precifica.com.br/index.php/Produtos?act=edit&id=15969092 | R37: 35.13 | S37: =COUNTIF('Marcas Target'!A:A,dados!$E37)>0 -> FALSE
... A40: 1076459 | B40: Café Torrado e Moído Tradicional MELITTA Pacote 500g | C40: Alimentos | D40: Básico da despensa | E40: pa | H40: 7891021005043 | I40: 1076459 | J40: www.paodeacucar.com | K40: https://www.paodeacucar.com/produto/322383/cafe-torrado-e-moido-tradicional-melitta-pacote-500g | L40: 46087 | M40: 38.99 | N40: 38.99 | O40: 24 | P40: 23 | Q40: https://monitor.precifica.com.br/index.php/Produtos?act=edit&id=15969161 | R40: 94.37 | S40: =COUNTIF('Marcas Target'!A:A,dados!$E40)>0 -> FALSE
A41: 1130391 | B41: Café em Cápsula Torrado e Moído Lungo Espresso L\'or Caixa 52g 10 Unidades | C41: Alimentos | D41: Básico da despensa | E41: pa | H41: 7896089088335 | I41: 1130391 | J41: www.paodeacucar.com | K41: https://www.paodeacucar.com/produto/389387/cafe-em-capsula-torrado-e-moido-lungo-espresso-lor-caixa-52g-10-unidades | L41: 46089 | M41: 30.99 | N41: 30.99 | O41: 22 | P41: 22 | Q41: https://monitor.precifica.com.br/index.php/Produtos?act=edit&id=15969277 | S41: =COUNTIF('Marcas Target'!A:A,dados!$E41)>0 -> FALSE
A42: 1130391 | B42: Café em Cápsula Torrado e Moído Lungo Espresso L\'or Caixa 52g 10 Unidades | C42: Alimentos | D42: Básico da despensa | E42: pa | H42: 7896089088335 | I42: 1130391 | J42: www.paodeacucar.com | K42: https://www.paodeacucar.com/produto/389387/cafe-em-capsula-torrado-e-moido-lungo-espresso-lor-caixa-52g-10-unidades | L42: 46088 | M42: 30.99 | N42: 30.99 | O42: 24 | P42: 24 | Q42: https://monitor.precifica.com.br/index.php/Produtos?act=edit&id=15969277 | S42: =COUNTIF('Marcas Target'!A:A,dados!$E42)>0 -> FALSE
...

Sheet Sheet1
B1: Código de Barras | C1: Código
B2: 7896089013399 | C2: 1038723
B3: 7896089013399 | C3: 1038723
B4: 7896089013399 | C4: 1038723
B5: 7896005801529 | C5: 0183567
B6: 7896005801529 | C6: 0183567
B7: 7896005801529 | C7: 0183567
B8: 7896005800010 | C8: 0590655
B9: 7896005800010 | C9: 0590655
B10: 7896005800010 | C10: 0590655
B11: 7896005800188 | C11: 0463478
B12: 7896005800188 | C12: 0463478
... B1048: 7896005809488 | C1048: 1351082

Sheet Marcas Target
A1: Marcas Target | B1: Amostras na base
A2: ORFEU | B2: =COUNTIFS(dados!P:P,">0",dados!E:E,'Marcas Target'!A2) -> 62
A3: SANTA MONICA | B3: =COUNTIFS(dados!P:P,">0",dados!E:E,'Marcas Target'!A3) -> 35
A4: ASTRO CAFE | B4: =COUNTIFS(dados!P:P,">0",dados!E:E,'Marcas Target'!A4) -> 13
A5: L'OR | B5: =COUNTIFS(dados!P:P,">0",dados!E:E,'Marcas Target'!A5) -> 88
A6: BAGGIO | B6: =COUNTIFS(dados!P:P,">0",dados!E:E,'Marcas Target'!A6) -> 51
A7: CAFÉ DO CENTRO | B7: =COUNTIFS(dados!P:P,">0",dados!E:E,'Marcas Target'!A7) -> 6
A8: BRAVO | B8: =COUNTIFS(dados!P:P,">0",dados!E:E,'Marcas Target'!A8) -> 3
A9: CAFÉ TOLEDO | B9: =COUNTIFS(dados!P:P,">0",dados!E:E,'Marcas Target'!A9) -> 0
A10: TRES CORACOES | B10: =COUNTIFS(dados!P:P,">0",dados!E:E,'Marcas Target'!A10) -> 3
A11: CONSTANTINO | B11: =COUNTIFS(dados!P:P,">0",dados!E:E,'Marcas Target'!A11) -> 11
A12: ZARO CAFÉ | B12: =COUNTIFS(dados!P:P,">0",dados!E:E,'Marcas Target'!A12) -> 0
A13: COSTA RICA | B13: =COUNTIFS(dados!P:P,">0",dados!E:E,'Marcas Target'!A13) -> 0
A14: LAVAZZA | B14: =COUNTIFS(dados!P:P,">0",dados!E:E,'Marcas Target'!A14) -> 0

Sheet mambo
A1: SKU | B1: Titulo | C1: Fabricante | D1: Tipo Produto | E1: Departamento | F1: Categoria | G1: Sub Categoria | H1: GTIN | I1: Modelo | J1: Bytes | K1: Litros | L1: Tamanho | M1: Qtde. Pacote | N1: Cor | O1: Peso | P1: Genero | Q1: Volume | R1: Voltagem | S1: Disponibilidade | T1: Preco | U1: Preço Oferta | V1: Vendedor | W1: Descricao | X1: Descricao_1 | Y1: URL | Z1: URL Imagem | AA1: URL Imagem_2 | AB1: Column1 | AC1: _3 | AD1: _4 | AE1: _5 | AF1: _6 | AG1: _7 | AH1: _8 | AI1: _9 | AJ1: _10 | AK1: _11 | AL1: CLUSTER PAO
A2: 2532 | B2: Café Torrado e Moído Superior Aviação 500g | C2: Aviação | E2: Mambo | F2: Mercearia | H2: 7896331100648 | O2: 500 | S2: Disponivel | T2: 54.98 | U2: 54.98 | V2: SUPERMERCADOS MAMBO - BR | Y2: https://www.mambo.com.br/cafe-superior-moido-aviacao-500g/p | Z2: https://mambodelivery.vteximg.com.br/arquivos/ids/225965/_--15-.jpg?v=638726318458270000 | AA2: https://mambodelivery.vteximg.com.br/arquivos/ids/225965/_--15-.jpg?v=638726318458270000 | AB2: https://mambodelivery.vteximg.com.br/arquivos/ids/225965/_--15-.jpg?v=638726318458270000 | AL2: =VLOOKUP(mambo!$H2,Sheet1!B:C,2,FALSE) -> #N/A
A3: 2533 | B3: Café Torrado e Moído 252 Graus a Vácuo Pilão 500g | C3: Pilão | E3: Mambo | F3: Mercearia | H3: 7896089013849 | O3: 252 | S3: Disponivel | T3: 43.49 | U3: 43.49 | V3: SUPERMERCADOS MAMBO - BR | Y3: https://www.mambo.com.br/cafe-torrado-e-moido-252-graus-a-vacuo-pilao-500g/p | Z3: https://mambodelivery.vteximg.com.br/arquivos/ids/232952/7896089013849.jpg?v=638844758945970000 | AA3: https://mambodelivery.vteximg.com.br/arquivos/ids/232952/7896089013849.jpg?v=638844758945970000 | AB3: https://mambodelivery.vteximg.com.br/arquivos/ids/232952/7896089013849.jpg?v=638844758945970000 | AL3: =VLOOKUP(mambo!$H3,Sheet1!B:C,2,FALSE) -> #N/A
A4: 2534 | B4: Café Torrado e Moído 252° Graus Abre & Fecha Pilão Sachê 500g | C4: Pilão | E4: Mambo | F4: Mercearia | H4: 7896089013856 | O4: 500 | S4: Disponivel | T4: 43.49 | U4: 43.49 | V4: SUPERMERCADOS MAMBO - BR | Y4: https://www.mambo.com.br/cafe-torrado-e-moido-252--graus-abre---fecha-pilao-sache-500g/p | Z4: https://mambodelivery.vteximg.com.br/arquivos/ids/232953/7896089013856_01.jpg?v=638844761397800000 | AA4: https://mambodelivery.vteximg.com.br/arquivos/ids/232953/7896089013856_01.jpg?v=638844761397800000 | AB4: https://mambodelivery.vteximg.com.br/arquivos/ids/232953/7896089013856_01.jpg?v=638844761397800000 | AC4: https://mambodelivery.vteximg.com.br/arquivos/ids/232954/7896089013856_02.jpg?v=638844761398100000 | AD4: https://mambodelivery.vteximg.com.br/arquivos/ids/232955/7896089013856_03.jpg?v=638844761398100000 | AL4: =VLOOKUP(mambo!$H4,Sheet1!B:C,2,FALSE) -> 7641688
A5: 2536 | B5: Café Torrado e Moído a Vácuo Tradicional 3 Corações Pacote 500g | C5: 3 Corações | E5: Mambo | F5: Mercearia | H5: 7896045102440 | O5: 500 | S5: Disponivel | T5: 27.99 | U5: 27.99 | V5: SUPERMERCADOS MAMBO - BR | Y5: https://www.mambo.com.br/cafe-torrado-e-moido-a-vacuo-tradicional-3-coracoes-pacote-500g/p | Z5: https://mambodelivery.vteximg.com.br/arquivos/ids/159910/cafe-a-vacuo-tradicional-3-coracoes-500g_1.jpg?v=637883137229130000 | AA5: https://mambodelivery.vteximg.com.br/arquivos/ids/159910/cafe-a-vacuo-tradicional-3-coracoes-500g_1.jpg?v=637883137229130000 | AB5: https://mambodelivery.vteximg.com.br/arquivos/ids/159910/cafe-a-vacuo-tradicional-3-coracoes-500g_1.jpg?v=637883137229130000 | AC5: https://mambodelivery.vteximg.com.br/arquivos/ids/159909/cafe-a-vacuo-tradicional-3-coracoes-500g.jpg?v=637883137219130000 | AD5: https://mambodelivery.vteximg.com.br/arquivos/ids/159911/cafe-a-vacuo-tradicional-3-coracoes-500g_2.jpg?v=637883137237900000 | AE5: https://mambodelivery.vteximg.com.br/arquivos/ids/159912/cafe-a-vacuo-tradicional-3-coracoes-500g_3.jpg?v=637883137247770000 | AF5: https://mambodelivery.vteximg.com.br/arquivos/ids/159913/cafe-a-vacuo-tradicional-3-coracoes-500g_4.jpg?v=637883137256070000 | AG5: https://mambodelivery.vteximg.com.br/arquivos/ids/159914/cafe-a-vacuo-tradicional-3-coracoes-500g_5.jpg?v=637883137266830000 | AH5: https://mambodelivery.vteximg.com.br/arquivos/ids/159915/cafe-a-vacuo-tradicional-3-coracoes-500g_6.jpg?v=637883137274030000 | AL5: =VLOOKUP(mambo!$H5,Sheet1!B:C,2,FALSE) -> #N/A
A6: 2537 | B6: Cápsula de Café Aqtivus 8 Delta 55g com 10 Unidades | C6: Delta Q | E6: Mambo | F6: Mercearia | H6: 5601082038537 | M6: 10 | O6: 55 | S6: Disponivel | T6: 28.49 | U6: 28.49 | V6: SUPERMERCADOS MAMBO - BR | Y6: https://www.mambo.com.br/cafe-aqtivus-8-delta-55g-com-10-capsulas/p | Z6: https://mambodelivery.vteximg.com.br/arquivos/ids/159916/cafe-aqtivus-8-delta-55g-com-10-capsulas.jpg?v=637883137287030000 | AA6: https://mambodelivery.vteximg.com.br/arquivos/ids/159916/cafe-aqtivus-8-delta-55g-com-10-capsulas.jpg?v=637883137287030000 | AB6: https://mambodelivery.vteximg.com.br/arquivos/ids/159916/cafe-aqtivus-8-delta-55g-com-10-capsulas.jpg?v=637883137287030000 | AL6: =VLOOKUP(mambo!$H6,Sheet1!B:C,2,FALSE) -> #N/A
A7: 2538 | B7: Café Torrado e Moído Aromatizado Amêndoas Torradas Floresta 100g | C7: Floresta | E7: Mambo | F7: Mercearia | H7: 7896393800029 | O7: 100 | S7: Disponivel | T7: 19.98 | U7: 19.98 | V7: SUPERMERCADOS MAMBO - BR | Y7: https://www.mambo.com.br/cafe-aromatizado-amendoas-torradas-floresta-100g/p | Z7: https://mambodelivery.vteximg.com.br/arquivos/ids/159917/cafe-aromatizado-amendoas-torradas-floresta-100g.jpg?v=637883137303130000 | AA7: https://mambodelivery.vteximg.com.br/arquivos/ids/159917/cafe-aromatizado-amendoas-torradas-floresta-100g.jpg?v=637883137303130000 | AB7: https://mambodelivery.vteximg.com.br/arquivos/ids/159917/cafe-aromatizado-amendoas-torradas-floresta-100g.jpg?v=637883137303130000 | AL7: =VLOOKUP(mambo!$H7,Sheet1!B:C,2,FALSE) -> #N/A
A8: 2539 | B8: Café Torrado e Moído Aromatizado Baunilha com Nozes Floresta 100g | C8: Floresta | E8: Mambo | F8: Mercearia | H8: 7896393800050 | O8: 100 | S8: Disponivel | T8: 19.98 | U8: 19.98 | V8: SUPERMERCADOS MAMBO - BR | Y8: https://www.mambo.com.br/cafe-aromatizado-baunilha-com-nozes-floresta-100g/p | Z8: https://mambodelivery.vteximg.com.br/arquivos/ids/159918/cafe-aromatizado-baunilha-com-nozes-floresta-100g.jpg?v=637883137318300000 | AA8: https://mambodelivery.vteximg.com.br/arquivos/ids/159918/cafe-aromatizado-baunilha-com-nozes-floresta-100g.jpg?v=637883137318300000 | AB8: https://mambodelivery.vteximg.com.br/arquivos/ids/159918/cafe-aromatizado-baunilha-com-nozes-floresta-100g.jpg?v=637883137318300000 | AL8: =VLOOKUP(mambo!$H8,Sheet1!B:C,2,FALSE) -> #N/A
A9: 2541 | B9: Café Torrado e Moído Aromatizado Crème Brulée Floresta 100g | C9: Floresta | E9: Mambo | F9: Mercearia | H9: 7896393800067 | O9: 100 | S9: Disponivel | T9: 19.98 | U9: 19.98 | V9: SUPERMERCADOS MAMBO - BR | Y9: https://www.mambo.com.br/cafe-aromatizado-creme-brulee-floresta-100g/p | Z9: https://mambodelivery.vteximg.com.br/arquivos/ids/241367/209268.jpg?v=639010679039500000 | AA9: https://mambodelivery.vteximg.com.br/arquivos/ids/241367/209268.jpg?v=639010679039500000 | AB9: https://mambodelivery.vteximg.com.br/arquivos/ids/241367/209268.jpg?v=639010679039500000 | AL9: =VLOOKUP(mambo!$H9,Sheet1!B:C,2,FALSE) -> #N/A
A10: 2542 | B10: Café Torrado e Moído Aromatizado Trufas com Chocolate Floresta 100g | C10: Floresta | E10: Mambo | F10: Mercearia | H10: 7896393800074 | O10: 100 | S10: Disponivel | T10: 19.98 | U10: 19.98 | V10: SUPERMERCADOS MAMBO - BR | Y10: https://www.mambo.com.br/cafe-aromatizado-trufas-com-chocolate-floresta-100g/p | Z10: https://mambodelivery.vteximg.com.br/arquivos/ids/159921/cafe-aromatizado-trufas-com-chocolate-floresta-100g.jpg?v=637883137363370000 | AA10: https://mambodelivery.vteximg.com.br/arquivos/ids/159921/cafe-aromatizado-trufas-com-chocolate-floresta-100g.jpg?v=637883137363370000 | AB10: https://mambodelivery.vteximg.com.br/arquivos/ids/159921/cafe-aromatizado-trufas-com-chocolate-floresta-100g.jpg?v=637883137363370000 | AL10: =VLOOKUP(mambo!$H10,Sheet1!B:C,2,FALSE) -> #N/A
A11: 2543 | B11: Cápsula de Café Barítono Bravo 50g com 10 Unidades | C11: Bravo Café | E11: Mambo | F11: Mercearia | H11: 7898204020329 | M11: 10 | O11: 50 | S11: Disponivel | T11: 23.98 | U11: 23.98 | V11: SUPERMERCADOS MAMBO - BR | Y11: https://www.mambo.com.br/cafe-baritono-bravo-50g-com-10-capsulas/p | Z11: https://mambodelivery.vteximg.com.br/arquivos/ids/231793/226322.jpg.jpg?v=638822109508970000 | AA11: https://mambodelivery.vteximg.com.br/arquivos/ids/231793/226322.jpg.jpg?v=638822109508970000 | AB11: https://mambodelivery.vteximg.com.br/arquivos/ids/231793/226322.jpg.jpg?v=638822109508970000 | AL11: =VLOOKUP(mambo!$H11,Sheet1!B:C,2,FALSE) -> #N/A
A12: 2545 | B12: Cápsula de Café Blonde Espresso Roast Starbucks & Nespresso com 10 Unidades | C12: Nescafé | E12: Mambo | F12: Mercearia | H12: 7613036961004 | M12: 10 | S12: Disponivel | T12: 32.98 | U12: 32.98 | V12: SUPERMERCADOS MAMBO - BR | Y12: https://www.mambo.com.br/cafe-blonde-espresso-roast-starbucks-by-nespresso-com-10-capsulas/p | Z12: https://mambodelivery.vteximg.com.br/arquivos/ids/223502/7613036961004-CafeemCapsulaStarbucks%C3%82%C2%AEBlondeEspressoRoastbyNespresso%C3%82%C2%AE-10capsulas-1.jpg?v=638664166610400000 | AA12: https://mambodelivery.vteximg.com.br/arquivos/ids/223502/7613036961004-CafeemCapsulaStarbucks%C3%82%C2%AEBlondeEspressoRoastbyNespresso%C3%82%C2%AE-10capsulas-1.jpg?v=638664166610400000 | AB12: https://mambodelivery.vteximg.com.br/arquivos/ids/223502/7613036961004-CafeemCapsulaStarbucks%C3%82%C2%AEBlondeEspressoRoastbyNespresso%C3%82%C2%AE-10capsulas-1.jpg?v=638664166610400000 | AC12: https://mambodelivery.vteximg.com.br/arquivos/ids/223503/image-to-upload-1.jpg?v=638664166614930000 | AD12: https://mambodelivery.vteximg.com.br/arquivos/ids/223504/7613036961004-CafeemCapsulaStarbucks%C3%82%C2%AEBlondeEspressoRoastbyNespresso%C3%82%C2%AE-10capsulas-1.jpg?v=638664166618700000 | AE12: https://mambodelivery.vteximg.com.br/arquivos/ids/223505/7613036961004-CafeemCapsulaStarbucks%C3%82%C2%AEBlondeEspressoRoastbyNespresso%C3%82%C2%AE-10capsulas-3.jpg?v=638664166622130000 | AF12: https://mambodelivery.vteximg.com.br/arquivos/ids/223506/7613036961004-CafeemCapsulaStarbucks%C3%82%C2%AEBlondeEspressoRoastbyNespresso%C3%82%C2%AE-10capsulas-4.jpg?v=638664166625070000 | AG12: https://mambodelivery.vteximg.com.br/arquivos/ids/223507/7613036961004-CafeemCapsulaStarbucks%C3%82%C2%AEBlondeEspressoRoastbyNespresso%C3%82%C2%AE-10capsulas-5.jpg?v=638664166627730000 | AL12: =VLOOKUP(mambo!$H12,Sheet1!B:C,2,FALSE) -> 1194407
A13: 2545 | B13: Cápsula de Café Blonde Espresso Roast Starbucks & Nespresso com 10 Unidades | C13: Nescafé | E13: Mambo | F13: Mercearia | H13: 7613036961004 | M13: 10 | S13: Disponivel | T13: 32.98 | U13: 32.98 | V13: SUPERMERCADOS MAMBO - BR | Y13: https://www.mambo.com.br/cafe-blonde-espresso-roast-starbucks-by-nespresso-com-10-capsulas/p | Z13: https://mambodelivery.vteximg.com.br/arquivos/ids/223502/7613036961004-CafeemCapsulaStarbucks%C3%82%C2%AEBlondeEspressoRoastbyNespresso%C3%82%C2%AE-10capsulas-1.jpg?v=638664166610400000 | AA13: https://mambodelivery.vteximg.com.br/arquivos/ids/223502/7613036961004-CafeemCapsulaStarbucks%C3%82%C2%AEBlondeEspressoRoastbyNespresso%C3%82%C2%AE-10capsulas-1.jpg?v=638664166610400000 | AB13: https://mambodelivery.vteximg.com.br/arquivos/ids/223502/7613036961004-CafeemCapsulaStarbucks%C3%82%C2%AEBlondeEspressoRoastbyNespresso%C3%82%C2%AE-10capsulas-1.jpg?v=638664166610400000 | AC13: https://mambodelivery.vteximg.com.br/arquivos/ids/223503/image-to-upload-1.jpg?v=638664166614930000 | AD13: https://mambodelivery.vteximg.com.br/arquivos/ids/223504/7613036961004-CafeemCapsulaStarbucks%C3%82%C2%AEBlondeEspressoRoastbyNespresso%C3%82%C2%AE-10capsulas-1.jpg?v=638664166618700000 | AE13: https://mambodelivery.vteximg.com.br/arquivos/ids/223505/7613036961004-CafeemCapsulaStarbucks%C3%82%C2%AEBlondeEspressoRoastbyNespresso%C3%82%C2%AE-10capsulas-3.jpg?v=638664166622130000 | AF13: https://mambodelivery.vteximg.com.br/arquivos/ids/223506/7613036961004-CafeemCapsulaStarbucks%C3%82%C2%AEBlondeEspressoRoastbyNespresso%C3%82%C2%AE-10capsulas-4.jpg?v=638664166625070000 | AG13: https://mambodelivery.vteximg.com.br/arquivos/ids/223507/7613036961004-CafeemCapsulaStarbucks%C3%82%C2%AEBlondeEspressoRoastbyNespresso%C3%82%C2%AE-10capsulas-5.jpg?v=638664166627730000 | AL13: =VLOOKUP(mambo!$H13,Sheet1!B:C,2,FALSE) -> 1194407
A14: 2546 | B14: Café Torrado e Moído Bourbon Amarelo Varietais Orfeu 250g | C14: Orfeu | E14: Mambo | F14: Mercearia | H14: 7898665830512 | O14: 250 | S14: Disponivel | T14: 42.49 | U14: 42.49 | V14: SUPERMERCADOS MAMBO - BR | Y14: https://www.mambo.com.br/cafe-torrado-e-moido-bourbon-amarelo-varietais-orfeu-250g/p | Z14: https://mambodelivery.vteximg.com.br/arquivos/ids/230121/270757.jpg.jpg?v=638792182938900000 | AA14: https://mambodelivery.vteximg.com.br/arquivos/ids/230121/270757.jpg.jpg?v=638792182938900000 | AB14: https://mambodelivery.vteximg.com.br/arquivos/ids/230121/270757.jpg.jpg?v=638792182938900000 | AL14: =VLOOKUP(mambo!$H14,Sheet1!B:C,2,FALSE) -> 1229373
A15: 2547 | B15: Cápsula de Café Bourbon Amarelo Orfeu 50g com 10 Unidades | C15: Orfeu | E15: Mambo | F15: Mercearia | H15: 7898665830499 | M15: 10 | O15: 50 | S15: Disponivel | T15: 26.99 | U15: 26.99 | V15: SUPERMERCADOS MAMBO - BR | Y15: https://www.mambo.com.br/cafe-bourbon-amarelo-orfeu-50g-com-10-capsulas/p | Z15: https://mambodelivery.vteximg.com.br/arquivos/ids/159939/cafe-bourbon-amarelo-orfeu-50g-com-10-capsulas.jpg?v=637883137569100000 | AA15: https://mambodelivery.vteximg.com.br/arquivos/ids/159939/cafe-bourbon-amarelo-orfeu-50g-com-10-capsulas.jpg?v=637883137569100000 | AB15: https://mambodelivery.vteximg.com.br/arquivos/ids/159939/cafe-bourbon-amarelo-orfeu-50g-com-10-capsulas.jpg?v=637883137569100000 | AL15: =VLOOKUP(mambo!$H15,Sheet1!B:C,2,FALSE) -> 1229374
A16: 2555 | B16: Cápsula de Café Clássico Orfeu 50g com 10 Unidades | C16: Orfeu | E16: Mambo | F16: Mercearia | H16: 7898912704085 | M16: 10 | O16: 50 | S16: Disponivel | T16: 26.99 | U16: 26.99 | V16: SUPERMERCADOS MAMBO - BR | Y16: https://www.mambo.com.br/cafe-classico-orfeu-50g-com-10-capsulas/p | Z16: https://mambodelivery.vteximg.com.br/arquivos/ids/159955/cafe-classico-orfeu-50g-com-10-capsulas.jpg?v=637883137770670000 | AA16: https://mambodelivery.vteximg.com.br/arquivos/ids/159955/cafe-classico-orfeu-50g-com-10-capsulas.jpg?v=637883137770670000 | AB16: https://mambodelivery.vteximg.com.br/arquivos/ids/159955/cafe-classico-orfeu-50g-com-10-capsulas.jpg?v=637883137770670000 | AL16: =VLOOKUP(mambo!$H16,Sheet1!B:C,2,FALSE) -> 1075263
A17: 2556 | B17: Cápsula de Café Single-Origin Colombia Nespresso Starbucks 57g com 10 Unidades | C17: Nescafé | E17: Mambo | F17: Mercearia | H17: 7613036961448 | M17: 10 | O17: 57 | S17: Disponivel | T17: 32.98 | U17: 32.98 | V17: SUPERMERCADOS MAMBO - BR | Y17: https://www.mambo.com.br/capsula-de-cafe-single-origin-colombia-nespresso-starbucks-57g-com-10-unidades/p | Z17: https://mambodelivery.vteximg.com.br/arquivos/ids/230887/7613036961448-CafeemCapsulaStarbucks%C3%82%C2%AESingle-OriginColombiabyNespresso%C3%82%C2%AE-10capsulas-1.jpg?v=638803142930800000 | AA17: https://mambodelivery.vteximg.com.br/arquivos/ids/230887/7613036961448-CafeemCapsulaStarbucks%C3%82%C2%AESingle-OriginColombiabyNespresso%C3%82%C2%AE-10capsulas-1.jpg?v=638803142930800000 | AB17: https://mambodelivery.vteximg.com.br/arquivos/ids/230887/7613036961448-CafeemCapsulaStarbucks%C3%82%C2%AESingle-OriginColombiabyNespresso%C3%82%C2%AE-10capsulas-1.jpg?v=638803142930800000 | AC17: https://mambodelivery.vteximg.com.br/arquivos/ids/230888/7613036961448-CafeemCapsulaStarbucks%C3%82%C2%AESingle-OriginColombiabyNespresso%C3%82%C2%AE-10capsulas-3.jpg?v=638803144120670000 | AD17: https://mambodelivery.vteximg.com.br/arquivos/ids/230889/7613036961448-CafeemCapsulaStarbucks%C3%82%C2%AESingle-OriginColombiabyNespresso%C3%82%C2%AE-10capsulas-4.jpg?v=638803144120670000 | AE17: https://mambodelivery.vteximg.com.br/arquivos/ids/230890/7613036961448-CafeemCapsulaStarbucks%C3%82%C2%AESingle-OriginColombiabyNespresso%C3%82%C2%AE-10capsulas-5.jpg?v=638803144120670000 | AF17: https://mambodelivery.vteximg.com.br/arquivos/ids/230891/7613036961448-CafeemCapsulaStarbucks%C3%82%C2%AESingle-OriginColombiabyNespresso%C3%82%C2%AE-10capsulas-6.jpg?v=638803144120670000 | AG17: https://mambodelivery.vteximg.com.br/arquivos/ids/230892/7613036961448-CafeemCapsulaStarbucks%C3%82%C2%AESingle-OriginColombiabyNespresso%C3%82%C2%AE-10capsulas-7.jpg?v=638803144120800000 | AH17: https://mambodelivery.vteximg.com.br/arquivos/ids/230893/7613036961448-CafeemCapsulaStarbucks%C3%82%C2%AESingle-OriginColombiabyNespresso%C3%82%C2%AE-10capsulas-8.jpg?v=638803144120800000 | AI17: https://mambodelivery.vteximg.com.br/arquivos/ids/230894/7613036961448-CafeemCapsulaStarbucks%C3%82%C2%AESingle-OriginColombiabyNespresso%C3%82%C2%AE-10capsulas-9.jpg?v=638803144120800000 | AL17: =VLOOKUP(mambo!$H17,Sheet1!B:C,2,FALSE) -> #N/A
A18: 2557 | B18: Cápsula de Café com Cacau Italle 25g com 10 Unidades | C18: Italle | E18: Mambo | F18: Mercearia | H18: 7898994748762 | M18: 10 | O18: 25 | S18: Disponivel | T18: 18.99 | U18: 18.99 | V18: SUPERMERCADOS MAMBO - BR | Y18: https://www.mambo.com.br/cafe-com-cacau-italle-25g-10-capsulas/p | Z18: https://mambodelivery.vteximg.com.br/arquivos/ids/159966/cafc3a9-com-cacau-italle-25g-10-cc3a1psulas.jpg?v=637883137892930000 | AA18: https://mambodelivery.vteximg.com.br/arquivos/ids/159966/cafc3a9-com-cacau-italle-25g-10-cc3a1psulas.jpg?v=637883137892930000 | AB18: https://mambodelivery.vteximg.com.br/arquivos/ids/159966/cafc3a9-com-cacau-italle-25g-10-cc3a1psulas.jpg?v=637883137892930000 | AL18: =VLOOKUP(mambo!$H18,Sheet1!B:C,2,FALSE) -> #N/A
A19: 2559 | B19: Cápsula de Café Com Leite Tres 3 Corações 90g com 10 Unidades | C19: 3 Corações | E19: Mambo | F19: Mercearia | H19: 7896005805121 | M19: 10 | O19: 90 | S19: Disponivel | T19: 17.98 | U19: 17.98 | V19: SUPERMERCADOS MAMBO - BR | Y19: https://www.mambo.com.br/capsula-de-cafe-com-leite-tres-3-coracoes-90g-com-10-unidades/p | Z19: https://mambodelivery.vteximg.com.br/arquivos/ids/211423/7896005805121-Capsula-de-Cafe-com-Leite-3-Coracoes-10-unid-01.jpg?v=638531991024200000 | AA19: https://mambodelivery.vteximg.com.br/arquivos/ids/211423/7896005805121-Capsula-de-Cafe-com-Leite-3-Coracoes-10-unid-01.jpg?v=638531991024200000 | AB19: https://mambodelivery.vteximg.com.br/arquivos/ids/211423/7896005805121-Capsula-de-Cafe-com-Leite-3-Coracoes-10-unid-01.jpg?v=638531991024200000 | AC19: https://mambodelivery.vteximg.com.br/arquivos/ids/211424/7896005805121-Capsula-de-Cafe-com-Leite-3-Coracoes-10-unid-02.jpg?v=638755917606600000 | AD19: https://mambodelivery.vteximg.com.br/arquivos/ids/211425/7896005805121-Capsula-de-Cafe-com-Leite-3-Coracoes-10-unid-03.jpg?v=638755917606600000 | AE19: https://mambodelivery.vteximg.com.br/arquivos/ids/211426/7896005805121-Capsula-de-Cafe-com-Leite-3-Coracoes-10-unid-04.jpg?v=638755917606600000 | AL19: =VLOOKUP(mambo!$H19,Sheet1!B:C,2,FALSE) -> 1042388
A20: 2561 | B20: Cápsula de Café Baileys Supremo Macchiato Tres 3 Corações 110g com 10 Unidades | C20: 3 Corações | E20: Mambo | F20: Mercearia | H20: 7896045104871 | M20: 10 | O20: 110 | S20: Disponivel | T20: 17.98 | U20: 17.98 | V20: SUPERMERCADOS MAMBO - BR | Y20: https://www.mambo.com.br/capsula-baileys-supremo-macchiato-3-coracoes-10-unid/p | Z20: https://mambodelivery.vteximg.com.br/arquivos/ids/227641/7896045104871---Cafe-com-Leite-em-Capsula-Supremo-Macchiato-3-Coracoes-Baileys-Caixa-110g-10-Unidades---1.jpg?v=638762701443930000 | AA20: https://mambodelivery.vteximg.com.br/arquivos/ids/227641/7896045104871---Cafe-com-Leite-em-Capsula-Supremo-Macchiato-3-Coracoes-Baileys-Caixa-110g-10-Unidades---1.jpg?v=638762701443930000 | AB20: https://mambodelivery.vteximg.com.br/arquivos/ids/227641/7896045104871---Cafe-com-Leite-em-Capsula-Supremo-Macchiato-3-Coracoes-Baileys-Caixa-110g-10-Unidades---1.jpg?v=638762701443930000 | AC20: https://mambodelivery.vteximg.com.br/arquivos/ids/227642/7896045104871---Cafe-com-Leite-em-Capsula-Supremo-Macchiato-3-Coracoes-Baileys-Caixa-110g-10-Unidades---1.jpg?v=638762701444100000 | AD20: https://mambodelivery.vteximg.com.br/arquivos/ids/227643/7896045104871---Cafe-com-Leite-em-Capsula-Supremo-Macchiato-3-Coracoes-Baileys-Caixa-110g-10-Unidades---2.jpg?v=638762701444100000 | AE20: https://mambodelivery.vteximg.com.br/arquivos/ids/227644/7896045104871---Cafe-com-Leite-em-Capsula-Supremo-Macchiato-3-Coracoes-Baileys-Caixa-110g-10-Unidades---3.jpg?v=638762701444100000 | AL20: =VLOOKUP(mambo!$H20,Sheet1!B:C,2,FALSE) -> 1328047
A21: 2568 | B21: Cápsula de Café Espresso Forza Tres 3 Corações 80g com 10 Unidades | C21: 3 Corações | E21: Mambo | F21: Mercearia | H21: 7896045101733 | M21: 10 | O21: 80 | S21: Disponivel | T21: 17.98 | U21: 17.98 | V21: SUPERMERCADOS MAMBO - BR | Y21: https://www.mambo.com.br/capsula-de-cafe-espresso-forza-tres-3-coracoes-80g-com-10-unidades/p | Z21: https://mambodelivery.vteximg.com.br/arquivos/ids/227653/265764-Cafe-Capsula-Forza-Tres-8g-10-Capsulas.jpg?v=638762701820000000 | AA21: https://mambodelivery.vteximg.com.br/arquivos/ids/227653/265764-Cafe-Capsula-Forza-Tres-8g-10-Capsulas.jpg?v=638762701820000000 | AB21: https://mambodelivery.vteximg.com.br/arquivos/ids/227653/265764-Cafe-Capsula-Forza-Tres-8g-10-Capsulas.jpg?v=638762701820000000 | AC21: https://mambodelivery.vteximg.com.br/arquivos/ids/227654/265764-Cafe-Capsula-Forza-Tres-8g-10-Capsulas.jpg?v=638762701820330000 | AD21: https://mambodelivery.vteximg.com.br/arquivos/ids/227655/265764-Cafe-Capsula-Forza-Tres-8g-10-Capsulas.jpg?v=638762701820330000 | AE21: https://mambodelivery.vteximg.com.br/arquivos/ids/227656/265764-Cafe-Capsula-Forza-Tres-8g-10-Capsulas.jpg?v=638762701820330000 | AL21: =VLOOKUP(mambo!$H21,Sheet1!B:C,2,FALSE) -> 1251696
A22: 2572 | B22: Café Torrado e Moído Descafeinado a Vácuo 3 Corações 250g | C22: 3 Corações | E22: Mambo | F22: Mercearia | H22: 7896005800577 | O22: 250 | S22: Disponivel | T22: 40.98 | U22: 40.98 | V22: SUPERMERCADOS MAMBO - BR | Y22: https://www.mambo.com.br/cafe-torrado-e-moido-descafeinado-a-vacuo-3-coracoes-250g/p | Z22: https://mambodelivery.vteximg.com.br/arquivos/ids/227182/cafe-descafeinado-a-vacuo-3-coracoes-250g_1.jpg?v=638760218489770000 | AA22: https://mambodelivery.vteximg.com.br/arquivos/ids/227182/cafe-descafeinado-a-vacuo-3-coracoes-250g_1.jpg?v=638760218489770000 | AB22: https://mambodelivery.vteximg.com.br/arquivos/ids/227182/cafe-descafeinado-a-vacuo-3-coracoes-250g_1.jpg?v=638760218489770000 | AC22: https://mambodelivery.vteximg.com.br/arquivos/ids/227183/cafe-descafeinado-a-vacuo-3-coracoes-250g.jpg?v=638760218489930000 | AD22: https://mambodelivery.vteximg.com.br/arquivos/ids/227184/cafe-descafeinado-a-vacuo-3-coracoes-250g_2.jpg?v=638760218490100000 | AE22: https://mambodelivery.vteximg.com.br/arquivos/ids/227185/cafe-descafeinado-a-vacuo-3-coracoes-250g_3.jpg?v=638760218490100000 | AF22: https://mambodelivery.vteximg.com.br/arquivos/ids/227186/cafe-descafeinado-a-vacuo-3-coracoes-250g_4.jpg?v=638760218490100000 | AG22: https://mambodelivery.vteximg.com.br/arquivos/ids/227187/cafe-descafeinado-a-vacuo-3-coracoes-250g_5.jpg?v=638760218490230000 | AH22: https://mambodelivery.vteximg.com.br/arquivos/ids/227188/cafe-descafeinado-a-vacuo-3-coracoes-250g_6.jpg?v=638760218490230000 | AL22: =VLOOKUP(mambo!$H22,Sheet1!B:C,2,FALSE) -> 4586951
A23: 2573 | B23: Café Torrado e Moído Descafeinado Melitta 250g | C23: Melitta | E23: Mambo | F23: Mercearia | H23: 7891021006309 | O23: 250 | S23: Disponivel | T23: 40.98 | U23: 40.98 | V23: SUPERMERCADOS MAMBO - BR | Y23: https://www.mambo.com.br/cafe-torrado-e-moido-descafeinado-melitta-250g/p | Z23: https://mambodelivery.vteximg.com.br/arquivos/ids/227280/cafe-descafeinado-melitta-250g_1.jpg?v=638761902420200000 | AA23: https://mambodelivery.vteximg.com.br/arquivos/ids/227280/cafe-descafeinado-melitta-250g_1.jpg?v=638761902420200000 | AB23: https://mambodelivery.vteximg.com.br/arquivos/ids/227280/cafe-descafeinado-melitta-250g_1.jpg?v=638761902420200000 | AC23: https://mambodelivery.vteximg.com.br/arquivos/ids/227281/cafe-descafeinado-melitta-250g.jpg?v=638761902420370000 | AD23: https://mambodelivery.vteximg.com.br/arquivos/ids/227282/cafe-descafeinado-melitta-250g_2.jpg?v=638761902420500000 | AE23: https://mambodelivery.vteximg.com.br/arquivos/ids/227283/cafe-descafeinado-melitta-250g_3.jpg?v=638761902420500000 | AL23: =VLOOKUP(mambo!$H23,Sheet1!B:C,2,FALSE) -> #N/A
A24: 2575 | B24: Café Torrado e Moído Descafeínado a Vácuo Pilão 250g | C24: Pilão | E24: Mambo | F24: Mercearia | H24: 7896089012118 | O24: 250 | S24: Disponivel | T24: 40.98 | U24: 40.98 | V24: SUPERMERCADOS MAMBO - BR | Y24: https://www.mambo.com.br/cafe-torrado-e-moido-descafeinado-a-vacuo-pilao-250g/p | Z24: https://mambodelivery.vteximg.com.br/arquivos/ids/232900/7896089012118_03.jpg?v=638844663495870000 | AA24: https://mambodelivery.vteximg.com.br/arquivos/ids/232900/7896089012118_03.jpg?v=638844663495870000 | AB24: https://mambodelivery.vteximg.com.br/arquivos/ids/232900/7896089012118_03.jpg?v=638844663495870000 | AC24: https://mambodelivery.vteximg.com.br/arquivos/ids/232901/7896089012118_02.jpg?v=638844663495870000 | AD24: https://mambodelivery.vteximg.com.br/arquivos/ids/232902/7896089012118_01.jpg?v=638844663496030000 | AL24: =VLOOKUP(mambo!$H24,Sheet1!B:C,2,FALSE) -> 0573313
A25: 2577 | B25: Cápsula de Café Orgânico Santa Mônica 50g com 10 Unidades | C25: Santa Mônica | E25: Mambo | F25: Mercearia | H25: 7898372620109 | M25: 10 | O25: 50 | S25: Indisponivel | T25: 0 | U25: 0 | Y25: https://www.mambo.com.br/capsula-de-cafe-organico-santa-monica-50g-10-unidades/p | Z25: https://mambodelivery.vteximg.com.br/arquivos/ids/160026/cafe-em-capsula-organico-santa-monica-50g-10-unidades.jpg?v=637883138574500000 | AA25: https://mambodelivery.vteximg.com.br/arquivos/ids/160026/cafe-em-capsula-organico-santa-monica-50g-10-unidades.jpg?v=637883138574500000 | AB25: https://mambodelivery.vteximg.com.br/arquivos/ids/160026/cafe-em-capsula-organico-santa-monica-50g-10-unidades.jpg?v=637883138574500000 | AL25: =VLOOKUP(mambo!$H25,Sheet1!B:C,2,FALSE) -> 1405510
A26: 2578 | B26: Cápsula de Café Bourbon Amarelo Orfeu 50g com 10 Unidades | C26: Orfeu | E26: Mambo | F26: Mercearia | H26: 7898665831298 | M26: 10 | O26: 50 | S26: Disponivel | T26: 29.99 | U26: 29.99 | V26: SUPERMERCADOS MAMBO - BR | Y26: https://www.mambo.com.br/capsula-de-cafe-bourbon-amarelo-orfeu-50g-10-unidades/p | Z26: https://mambodelivery.vteximg.com.br/arquivos/ids/160027/cafe-em-capsula-bourbon-amarelo-orfeu-10-unidades.jpg?v=637883138588600000 | AA26: https://mambodelivery.vteximg.com.br/arquivos/ids/160027/cafe-em-capsula-bourbon-amarelo-orfeu-10-unidades.jpg?v=637883138588600000 | AB26: https://mambodelivery.vteximg.com.br/arquivos/ids/160027/cafe-em-capsula-bourbon-amarelo-orfeu-10-unidades.jpg?v=637883138588600000 | AL26: =VLOOKUP(mambo!$H26,Sheet1!B:C,2,FALSE) -> #N/A
A27: 2579 | B27: Cápsula de Café Clássico Orfeu 90g com 10 Unidades | C27: Orfeu | E27: Mambo | F27: Mercearia | H27: 7898665831274 | M27: 10 | O27: 90 | S27: Disponivel | T27: 29.99 | U27: 29.99 | V27: SUPERMERCADOS MAMBO - BR | Y27: https://www.mambo.com.br/capsula-de-cafe-classico-orfeu-90g-10-unidades/p | Z27: https://mambodelivery.vteximg.com.br/arquivos/ids/160028/cafe-em-capsula-classico-orfeu-10-unidades.jpg?v=637883138603130000 | AA27: https://mambodelivery.vteximg.com.br/arquivos/ids/160028/cafe-em-capsula-classico-orfeu-10-unidades.jpg?v=637883138603130000 | AB27: https://mambodelivery.vteximg.com.br/arquivos/ids/160028/cafe-em-capsula-classico-orfeu-10-unidades.jpg?v=637883138603130000 | AL27: =VLOOKUP(mambo!$H27,Sheet1!B:C,2,FALSE) -> #N/A
A28: 2582 | B28: Cápsula de Café Intenso Orfeu 90g com 10 Unidades | C28: Orfeu | E28: Mambo | F28: Mercearia | H28: 7898665831281 | M28: 10 | O28: 90 | S28: Disponivel | T28: 29.99 | U28: 29.99 | V28: SUPERMERCADOS MAMBO - BR | Y28: https://www.mambo.com.br/capsula-de-cafe-intenso-orfeu-90g-10-unidades/p | Z28: https://mambodelivery.vteximg.com.br/arquivos/ids/160031/cafe-em-capsula-intenso-orfeu-10-unidades.png?v=637883138643800000 | AA28: https://mambodelivery.vteximg.com.br/arquivos/ids/160031/cafe-em-capsula-intenso-orfeu-10-unidades.png?v=637883138643800000 | AB28: https://mambodelivery.vteximg.com.br/arquivos/ids/160031/cafe-em-capsula-intenso-orfeu-10-unidades.png?v=637883138643800000 | AL28: =VLOOKUP(mambo!$H28,Sheet1!B:C,2,FALSE) -> #N/A
A29: 2583 | B29: Cápsula de Café Orgânico Orfeu 90g com 10 Unidades | C29: Orfeu | E29: Mambo | F29: Mercearia | H29: 7898665831304 | M29: 10 | O29: 90 | S29: Disponivel | T29: 36.98 | U29: 36.98 | V29: SUPERMERCADOS MAMBO - BR | Y29: https://www.mambo.com.br/capsula-de-cafe-organico-orfeu-90g-10-unidades/p | Z29: https://mambodelivery.vteximg.com.br/arquivos/ids/160032/cafe-em-capsula-organico-orfeu-10-unidades.jpg?v=637883138658200000 | AA29: https://mambodelivery.vteximg.com.br/arquivos/ids/160032/cafe-em-capsula-organico-orfeu-10-unidades.jpg?v=637883138658200000 | AB29: https://mambodelivery.vteximg.com.br/arquivos/ids/160032/cafe-em-capsula-organico-orfeu-10-unidades.jpg?v=637883138658200000 | AL29: =VLOOKUP(mambo!$H29,Sheet1!B:C,2,FALSE) -> #N/A
A30: 2585 | B30: Cápsula de Café Torrado e Moído Clássico Espresso Illy Caixa 57g com 10 Unidades | C30: Illy | E30: Mambo | F30: Mercearia | H30: 8003753158679 | M30: 10 | O30: 57 | S30: Disponivel | T30: 24.99 | U30: 24.99 | V30: SUPERMERCADOS MAMBO - BR | Y30: https://www.mambo.com.br/capsula-de-cafe-torrado-e-moido-classico-espresso-illy-57g-10-unidades/p | Z30: https://mambodelivery.vteximg.com.br/arquivos/ids/160034/cafe-em-capsula-torrado-e-moido-classico-espresso-illy-caixa-57g-10-unidades.jpg?v=637883138690130000 | AA30: https://mambodelivery.vteximg.com.br/arquivos/ids/160034/cafe-em-capsula-torrado-e-moido-classico-espresso-illy-caixa-57g-10-unidades.jpg?v=637883138690130000 | AB30: https://mambodelivery.vteximg.com.br/arquivos/ids/160034/cafe-em-capsula-torrado-e-moido-classico-espresso-illy-caixa-57g-10-unidades.jpg?v=637883138690130000 | AC30: https://mambodelivery.vteximg.com.br/arquivos/ids/160035/cafe-em-capsula-torrado-e-moido-classico-espresso-illy-caixa-57g-10-unidades_1.jpg?v=637883138702330000 | AD30: https://mambodelivery.vteximg.com.br/arquivos/ids/160036/cafe-em-capsula-torrado-e-moido-classico-espresso-illy-caixa-57g-10-unidades_2.jpg?v=637883138714200000 | AL30: =VLOOKUP(mambo!$H30,Sheet1!B:C,2,FALSE) -> 1244783
A31: 2587 | B31: Cápsula de Café Forte Espresso Illy Caixa 57g com 10 Unidades | C31: Illy | E31: Mambo | F31: Mercearia | H31: 8003753158709 | M31: 10 | O31: 57 | S31: Disponivel | T31: 24.99 | U31: 24.99 | V31: SUPERMERCADOS MAMBO - BR | Y31: https://www.mambo.com.br/capsula-de-cafe-forte-espresso-illy-57g-10-unidades/p | Z31: https://mambodelivery.vteximg.com.br/arquivos/ids/160041/cafe-em-capsula-torrado-e-moido-forte-espresso-illy-caixa-57g-10-unidades.jpg?v=637883138768170000 | AA31: https://mambodelivery.vteximg.com.br/arquivos/ids/160041/cafe-em-capsula-torrado-e-moido-forte-espresso-illy-caixa-57g-10-unidades.jpg?v=637883138768170000 | AB31: https://mambodelivery.vteximg.com.br/arquivos/ids/160041/cafe-em-capsula-torrado-e-moido-forte-espresso-illy-caixa-57g-10-unidades.jpg?v=637883138768170000 | AC31: https://mambodelivery.vteximg.com.br/arquivos/ids/160042/cafe-em-capsula-torrado-e-moido-forte-espresso-illy-caixa-57g-10-unidades_1.jpg?v=637883138779400000 | AD31: https://mambodelivery.vteximg.com.br/arquivos/ids/160043/cafe-em-capsula-torrado-e-moido-forte-espresso-illy-caixa-57g-10-unidades_2.jpg?v=637883138788800000 | AL31: =VLOOKUP(mambo!$H31,Sheet1!B:C,2,FALSE) -> 1244781
A32: 2589 | B32: Cápsula de Café Intenso Espresso Illy Caixa 57g com 10 Unidades | C32: Illy | E32: Mambo | F32: Mercearia | H32: 8003753158761 | M32: 10 | O32: 57 | S32: Disponivel | T32: 24.99 | U32: 24.99 | V32: SUPERMERCADOS MAMBO - BR | Y32: https://www.mambo.com.br/capsula-de-cafe-intenso-espresso-illy-57g-10-unidades/p | Z32: https://mambodelivery.vteximg.com.br/arquivos/ids/160045/cafe-em-capsula-torrado-e-moido-intenso-espresso-illy-caixa-57g-10-unidades.jpg?v=637883138819000000 | AA32: https://mambodelivery.vteximg.com.br/arquivos/ids/160045/cafe-em-capsula-torrado-e-moido-intenso-espresso-illy-caixa-57g-10-unidades.jpg?v=637883138819000000 | AB32: https://mambodelivery.vteximg.com.br/arquivos/ids/160045/cafe-em-capsula-torrado-e-moido-intenso-espresso-illy-caixa-57g-10-unidades.jpg?v=637883138819000000 | AC32: https://mambodelivery.vteximg.com.br/arquivos/ids/160046/cafe-em-capsula-torrado-e-moido-intenso-espresso-illy-caixa-57g-10-unidades_1.jpg?v=637883138826970000 | AD32: https://mambodelivery.vteximg.com.br/arquivos/ids/160047/cafe-em-capsula-torrado-e-moido-intenso-espresso-illy-caixa-57g-10-unidades_2.jpg?v=637883138837770000 | AL32: =VLOOKUP(mambo!$H32,Sheet1!B:C,2,FALSE) -> 1244782
A33: 2595 | B33: Café em Grãos Classico Illy Blend 250g | C33: Illy | E33: Mambo | F33: Mercearia | H33: 8003753900520 | O33: 250 | S33: Disponivel | T33: 48.98 | U33: 48.98 | V33: SUPERMERCADOS MAMBO - BR | Y33: https://www.mambo.com.br/cafe-em-graos-torra-media-illy-250g/p | Z33: https://mambodelivery.vteximg.com.br/arquivos/ids/234211/230378.jpg?v=638863838396630000 | AA33: https://mambodelivery.vteximg.com.br/arquivos/ids/234211/230378.jpg?v=638863838396630000 | AB33: https://mambodelivery.vteximg.com.br/arquivos/ids/234211/230378.jpg?v=638863838396630000 | AL33: =VLOOKUP(mambo!$H33,Sheet1!B:C,2,FALSE) -> 4867753
A34: 2596 | B34: Cápsula de Café Epiq Intensidade 14 Delta Q 55g com 10 Unidades | C34: Delta Q | E34: Mambo | F34: Mercearia | H34: 5601082041162 | M34: 10 | O34: 55 | S34: Disponivel | T34: 28.49 | U34: 28.49 | V34: SUPERMERCADOS MAMBO - BR | Y34: https://www.mambo.com.br/cafe-epiq-intensidade-14-delta-q-55g-com-10-capsulas/p | Z34: https://mambodelivery.vteximg.com.br/arquivos/ids/160058/cafe-epiq-intensidade-14-delta-q-55g-com-10-capsulas.jpg?v=637883138997670000 | AA34: https://mambodelivery.vteximg.com.br/arquivos/ids/160058/cafe-epiq-intensidade-14-delta-q-55g-com-10-capsulas.jpg?v=637883138997670000 | AB34: https://mambodelivery.vteximg.com.br/arquivos/ids/160058/cafe-epiq-intensidade-14-delta-q-55g-com-10-capsulas.jpg?v=637883138997670000 | AL34: =VLOOKUP(mambo!$H34,Sheet1!B:C,2,FALSE) -> #N/A
A35: 2597 | B35: Café Torrado e Moído Especial a Vácuo Melitta 500g | C35: Melitta | E35: Mambo | F35: Mercearia | H35: 7891021006866 | O35: 500 | S35: Disponivel | T35: 56.98 | U35: 56.98 | V35: SUPERMERCADOS MAMBO - BR | Y35: https://www.mambo.com.br/cafe-torrado-e-moido-especial-a-vacuo-melitta-500g/p | Z35: https://mambodelivery.vteximg.com.br/arquivos/ids/227189/cafe-especial-a-vacuo-melitta-500g_2.jpg?v=638760220451770000 | AA35: https://mambodelivery.vteximg.com.br/arquivos/ids/227189/cafe-especial-a-vacuo-melitta-500g_2.jpg?v=638760220451770000 | AB35: https://mambodelivery.vteximg.com.br/arquivos/ids/227189/cafe-especial-a-vacuo-melitta-500g_2.jpg?v=638760220451770000 | AC35: https://mambodelivery.vteximg.com.br/arquivos/ids/227190/cafe-especial-a-vacuo-melitta-500g_1.jpg?v=638760220452000000 | AD35: https://mambodelivery.vteximg.com.br/arquivos/ids/227191/cafe-especial-a-vacuo-melitta-500g.jpg?v=638760220452170000 | AE35: https://mambodelivery.vteximg.com.br/arquivos/ids/227192/cafe-especial-a-vacuo-melitta-500g_3.jpg?v=638760220452200000 | AL35: =VLOOKUP(mambo!$H35,Sheet1!B:C,2,FALSE) -> #N/A
A36: 2598 | B36: Café em Cápsulas de Torrado e moído Pilão Fortíssimo 10 - 52g com 10 Cápsulas | C36: Pilão | E36: Mambo | F36: Mercearia | H36: 7896089088410 | M36: 10 | O36: 52 | S36: Disponivel | T36: 25.49 | U36: 25.49 | V36: SUPERMERCADOS MAMBO - BR | Y36: https://www.mambo.com.br/cafe-em-capsulas-de-torrado-e-moido-pilao-fortissimo-10---52g-com-10-capsulas/p | Z36: https://mambodelivery.vteximg.com.br/arquivos/ids/232913/7896089088410_01.jpg?v=638844672358530000 | AA36: https://mambodelivery.vteximg.com.br/arquivos/ids/232913/7896089088410_01.jpg?v=638844672358530000 | AB36: https://mambodelivery.vteximg.com.br/arquivos/ids/232913/7896089088410_01.jpg?v=638844672358530000 | AC36: https://mambodelivery.vteximg.com.br/arquivos/ids/232914/7896089088410_02.jpg?v=638844672358530000 | AD36: https://mambodelivery.vteximg.com.br/arquivos/ids/232915/7896089088410_03.jpg?v=638844672358530000 | AE36: https://mambodelivery.vteximg.com.br/arquivos/ids/232916/7896089088410_04.jpg?v=638844672358700000 | AF36: https://mambodelivery.vteximg.com.br/arquivos/ids/232917/7896089088410_05.jpg?v=638844672358700000 | AL36: =VLOOKUP(mambo!$H36,Sheet1!B:C,2,FALSE) -> 1148942
A37: 2599 | B37: Café em Cápsula Torrado e Moído Espresso Extraforte Pilão Caixa 52g 10 Unidades | C37: Pilão | E37: Mambo | F37: Mercearia | H37: 7896089088427 | M37: 10 | O37: 52 | S37: Disponivel | T37: 25.49 | U37: 25.49 | V37: SUPERMERCADOS MAMBO - BR | Y37: https://www.mambo.com.br/cafe-em-capsula-torrado-e-moido-espresso-extraforte-pilao-caixa-52g-10-unidades/p | Z37: https://mambodelivery.vteximg.com.br/arquivos/ids/232895/7896089088427_01.jpg?v=638844661510430000 | AA37: https://mambodelivery.vteximg.com.br/arquivos/ids/232895/7896089088427_01.jpg?v=638844661510430000 | AB37: https://mambodelivery.vteximg.com.br/arquivos/ids/232895/7896089088427_01.jpg?v=638844661510430000 | AC37: https://mambodelivery.vteximg.com.br/arquivos/ids/232896/7896089088427_02.jpg?v=638844661510570000 | AD37: https://mambodelivery.vteximg.com.br/arquivos/ids/232897/7896089088427_03.jpg?v=638844661510730000 | AE37: https://mambodelivery.vteximg.com.br/arquivos/ids/232898/7896089088427_04.jpg?v=638844661510730000 | AF37: https://mambodelivery.vteximg.com.br/arquivos/ids/232899/7896089088427_05.jpg?v=638844661510730000 | AL37: =VLOOKUP(mambo!$H37,Sheet1!B:C,2,FALSE) -> 1148946
